Workbook
Name Slicer_Department: #N/A
Name Slicer_Education_Field1: #N/A
Name Slicer_Gender: #N/A

Sheet Home

Sheet KPI
A3: Count of Employee Number | B3: Sum of CF_attrition count | C3: Average of Age | D3: Average of Years At Company | E3: Sum of Total Working Years
A4: 1470 | B4: 237 | C4: 36.92381 | D4: 7.0081633 | E4: 16581
A8: Count of Employee Number | B8: Sum of CF_attrition count | C8: Average of Age | D8: Average experience at Company | E8: Sum of Total Working Years | F8: Active Employees | G8: Attrition Rate
A9: =GETPIVOTDATA("Count of Employee Number",$A$3) -> 1470 | B9: =GETPIVOTDATA("Sum of CF_attrition count",$A$3) -> 237 | C9: =GETPIVOTDATA("Average of Age",$A$3) -> 36.92381 | D9: =GETPIVOTDATA("Average of Years At Company",$A$3) -> 7.0081633 | E9: =GETPIVOTDATA("Sum of Total Working Years",$A$3) -> 16581 | F9: =A9-B9 -> 1233 | G9: =B9/A9 -> 0.16122449

Sheet Rating
A3: Average of Job Satisfaction
A4: 2.6265306
A7: Rating | B7: =GETPIVOTDATA("Job Satisfaction",$A$3) -> 2.6265306 | C7: =B7/4 -> 0.65663265
A8: Balance Rating | B8: =4-B7 -> 1.3734694 | C8: =B8/4 -> 0.34336735

Sheet Gender
A3: Row Labels | B3: Sum of Employee Count
A4: Female | B4: 588
A5: Male | B5: 882
A6: Grand Total | B6: 1470
A11: Male | B11: =IFERROR(GETPIVOTDATA("Employee Count",$A$3,"Gender","Male"),0) -> 882 | C11: =IFERROR(B11/($B$11+$B$12),0) -> 0.6
A12: Female | B12: =IFERROR(GETPIVOTDATA("Employee Count",$A$3,"Gender","Female"),0) -> 588 | C12: =IFERROR(B12/($B$11+$B$12),0) -> 0.4

Sheet Detail1
A1: Details for Sum of CF_attrition count - Department: HR
A3: Attrition | B3: Business Travel | C3: CF_age band | D3: CF_attrition label | E3: Department | F3: Education Field | G3: emp no | H3: Employee Number | I3: Gender | J3: Job Role | K3: Marital Status | L3: Over Time | M3: Over18 | N3: Training Times Last Year | O3: -2 | P3: 0 | Q3: Age | R3: CF_attrition count | S3: CF_attrition counts | T3: CF_attrition rate | U3: CF_current Employee | V3: Daily Rate | W3: Distance From Home | X3: Education | Y3: Employee Count | Z3: Environment Satisfaction | AA3: Hourly Rate | AB3: Job Involvement | AC3: Job Level | AD3: Job Satisfaction | AE3: Monthly Income | AF3: Monthly Rate | AG3: Num Companies Worked | AH3: Percent Salary Hike | AI3: Performance Rating | AJ3: Relationship Satisfaction | AK3: Standard Hours | AL3: Stock Option Level | AM3: Total Working Years | AN3: Work Life Balance | AO3: Years At Company | AP3: Years In Current Role | AQ3: Years Since Last Promotion | AR3: Years With Curr Manager | AS3: Age Group | AT3: Group | AU3: Salary_Hike_Group | AV3: Years_in_company_group
A4: Yes | B4: Travel_Rarely | C4: 25 - 34 | D4: Ex-Employees | E4: HR | F4: Human Resources | G4: STAFF-1844 | H4: 1844 | I4: Male | J4: Human Resources | K4: Divorced | L4: Yes | M4: Y | N4: 3 | O4: -2 | P4: 0 | Q4: 29 | R4: 1 | S4: 1 | T4: 1 | U4: 0 | V4: 350 | W4: 13 | X4: Bachelor's Degree | Y4: 1 | Z4: 1 | AA4: 56 | AB4: 2 | AC4: 1 | AD4: 1 | AE4: 2335 | AF4: 3157 | AG4: 4 | AH4: 15 | AI4: 3 | AJ4: 4 | AK4: 80 | AL4: 3 | AM4: 4 | AN4: 3 | AO4: 2 | AP4: 2 | AQ4: 2 | AR4: 0 | AS4: 26-35 | AT4: Early Career | AU4: 13-15% | AV4: 0-2 Years
A5: Yes | B5: Travel_Rarely | C5: 25 - 34 | D5: Ex-Employees | E5: HR | F5: Medical | G5: STAFF-1818 | H5: 1818 | I5: Female | J5: Human Resources | K5: Married | L5: Yes | M5: Y | N5: 3 | O5: -2 | P5: 0 | Q5: 26 | R5: 1 | S5: 1 | T5: 1 | U5: 0 | V5: 920 | W5: 20 | X5: Associates Degree | Y5: 1 | Z5: 4 | AA5: 69 | AB5: 3 | AC5: 1 | AD5: 2 | AE5: 2148 | AF5: 6889 | AG5: 0 | AH5: 11 | AI5: 3 | AJ5: 3 | AK5: 80 | AL5: 0 | AM5: 6 | AN5: 3 | AO5: 5 | AP5: 1 | AQ5: 1 | AR5: 4 | AS5: 26-35 | AT5: Early Career | AU5: 10-12% | AV5: 3-5 Years
A6: Yes | B6: Travel_Rarely | C6: Under 25 | D6: Ex-Employees | E6: HR | F6: Human Resources | G6: STAFF-1714 | H6: 1714 | I6: Male | J6: Human Resources | K6: Married | L6: No | M6: Y | N6: 2 | O6: -2 | P6: 0 | Q6: 24 | R6: 1 | S6: 1 | T6: 1 | U6: 0 | V6: 240 | W6: 22 | X6: High School | Y6: 1 | Z6: 4 | AA6: 58 | AB6: 1 | AC6: 1 | AD6: 3 | AE6: 1555 | AF6: 11585 | AG6: 1 | AH6: 11 | AI6: 3 | AJ6: 3 | AK6: 80 | AL6: 1 | AM6: 1 | AN6: 3 | AO6: 1 | AP6: 0 | AQ6: 0 | AR6: 0 | AS6: 18-25 | AT6: Young | AU6: 10-12% | AV6: 0-2 Years
A7: Yes | B7: Travel_Rarely | C7: 25 - 34 | D7: Ex-Employees | E7: HR | F7: Human Resources | G7: STAFF-1842 | H7: 1842 | I7: Male | J7: Human Resources | K7: Married | L7: No | M7: Y | N7: 4 | O7: -2 | P7: 0 | Q7: 31 | R7: 1 | S7: 1 | T7: 1 | U7: 0 | V7: 359 | W7: 18 | X7: Doctoral Degree | Y7: 1 | Z7: 4 | AA7: 89 | AB7: 4 | AC7: 1 | AD7: 1 | AE7: 2956 | AF7: 21495 | AG7: 0 | AH7: 17 | AI7: 3 | AJ7: 3 | AK7: 80 | AL7: 0 | AM7: 2 | AN7: 3 | AO7: 1 | AP7: 0 | AQ7: 0 | AR7: 0 | AS7: 26-35 | AT7: Early Career | AU7: 16-18% | AV7: 0-2 Years
A8: Yes | B8: Travel_Rarely | C8: 25 - 34 | D8: Ex-Employees | E8: HR | F8: Technical Degree | G8: STAFF-1467 | H8: 1467 | I8: Female | J8: Human Resources | K8: Married | L8: No | M8: Y | N8: 0 | O8: -2 | P8: 0 | Q8: 34 | R8: 1 | S8: 1 | T8: 1 | U8: 0 | V8: 1107 | W8: 9 | X8: Master's Degree | Y8: 1 | Z8: 4 | AA8: 52 | AB8: 3 | AC8: 1 | AD8: 4 | AE8: 2742 | AF8: 3072 | AG8: 1 | AH8: 15 | AI8: 3 | AJ8: 4 | AK8: 80 | AL8: 0 | AM8: 2 | AN8: 3 | AO8: 2 | AP8: 2 | AQ8: 2 | AR8: 2 | AS8: 26-35 | AT8: Early Career | AU8: 13-15% | AV8: 0-2 Years
A9: Yes | B9: Travel_Frequently | C9: 25 - 34 | D9: Ex-Employees | E9: HR | F9: Human Resources | G9: STAFF-1944 | H9: 1944 | I9: Female | J9: Human Resources | K9: Married | L9: No | M9: Y | N9: 2 | O9: -2 | P9: 0 | Q9: 27 | R9: 1 | S9: 1 | T9: 1 | U9: 0 | V9: 1337 | W9: 22 | X9: Bachelor's Degree | Y9: 1 | Z9: 1 | AA9: 58 | AB9: 2 | AC9: 1 | AD9: 2 | AE9: 2863 | AF9: 19555 | AG9: 1 | AH9: 12 | AI9: 3 | AJ9: 1 | AK9: 80 | AL9: 0 | AM9: 1 | AN9: 3 | AO9: 1 | AP9: 0 | AQ9: 0 | AR9: 0 | AS9: 26-35 | AT9: Early Career | AU9: 10-12% | AV9: 0-2 Years
A10: Yes | B10: Travel_Frequently | C10: 25 - 34 | D10: Ex-Employees | E10: HR | F10: Human Resources | G10: STAFF-1747 | H10: 1747 | I10: Female | J10: Human Resources | K10: Divorced | L10: No | M10: Y | N10: 0 | O10: -2 | P10: 0 | Q10: 30 | R10: 1 | S10: 1 | T10: 1 | U10: 0 | V10: 600 | W10: 8 | X10: Bachelor's Degree | Y10: 1 | Z10: 3 | AA10: 66 | AB10: 2 | AC10: 1 | AD10: 4 | AE10: 2180 | AF10: 9732 | AG10: 6 | AH10: 11 | AI10: 3 | AJ10: 3 | AK10: 80 | AL10: 1 | AM10: 6 | AN10: 2 | AO10: 4 | AP10: 2 | AQ10: 1 | AR10: 2 | AS10: 26-35 | AT10: Early Career | AU10: 10-12% | AV10: 3-5 Years
A11: No | B11: Travel_Rarely | C11: 35 - 44 | D11: Current Employees | E11: HR | F11: Medical | G11: STAFF-1550 | H11: 1550 | I11: Male | J11: Manager | K11: Single | L11: Yes | M11: Y | N11: 2 | O11: -2 | P11: 0 | Q11: 40 | R11: 0 | T11: 0 | U11: 1 | V11: 898 | W11: 6 | X11: Associates Degree | Y11: 1 | Z11: 3 | AA11: 38 | AB11: 3 | AC11: 4 | AD11: 4 | AE11: 16437 | AF11: 17381 | AG11: 1 | AH11: 21 | AI11: 4 | AJ11: 4 | AK11: 80 | AL11: 0 | AM11: 21 | AN11: 3 | AO11: 21 | AP11: 7 | AQ11: 7 | AR11: 7 | AS11: 36-45 | AT11: Mid Career | AU11: 19-21% | AV11: 12+ Years
A12: No | B12: Travel_Rarely | C12: 25 - 34 | D12: Current Employees | E12: HR | F12: Life Sciences | G12: STAFF-1499 | H12: 1499 | I12: Male | J12: Human Resources | K12: Divorced | L12: No | M12: Y | N12: 3 | O12: -2 | P12: 0 | Q12: 30 | R12: 0 | T12: 0 | U12: 1 | V12: 330 | W12: 1 | X12: Bachelor's Degree | Y12: 1 | Z12: 3 | AA12: 46 | AB12: 3 | AC12: 1 | AD12: 3 | AE12: 2064 | AF12: 15428 | AG12: 0 | AH12: 21 | AI12: 4 | AJ12: 1 | AK12: 80 | AL12: 1 | AM12: 6 | AN12: 4 | AO12: 5 | AP12: 3 | AQ12: 1 | AR12: 3 | AS12: 26-35 | AT12: Early Career | AU12: 19-21% | AV12: 3-5 Years
A13: No | B13: Travel_Frequently | C13: 35 - 44 | D13: Current Employees | E13: HR | F13: Human Resources | G13: STAFF-1890 | H13: 1890 | I13: Male | J13: Human Resources | K13: Single | L13: No | M13: Y | N13: 2 | O13: -2 | P13: 0 | Q13: 36 | R13: 0 | T13: 0 | U13: 1 | V13: 1213 | W13: 2 | X13: High School | Y13: 1 | Z13: 2 | AA13: 94 | AB13: 2 | AC13: 2 | AD13: 4 | AE13: 3886 | AF13: 4223 | AG13: 1 | AH13: 21 | AI13: 4 | AJ13: 4 | AK13: 80 | AL13: 0 | AM13: 10 | AN13: 2 | AO13: 10 | AP13: 1 | AQ13: 0 | AR13: 8 | AS13: 36-45 | AT13: Mid Career | AU13: 19-21% | AV13: 9-11 Years
A14: No | B14: Travel_Rarely | C14: 45 - 54 | D14: Current Employees | E14: HR | F14: Life Sciences | G14: STAFF-1744 | H14: 1744 | I14: Female | J14: Human Resources | K14: Married | L14: No | M14: Y | N14: 2 | O14: -2 | P14: 0 | Q14: 45 | R14: 0 | T14: 0 | U14: 1 | V14: 176 | W14: 4 | X14: Bachelor's Degree | Y14: 1 | Z14: 3 | AA14: 56 | AB14: 1 | AC14: 3 | AD14: 3 | AE14: 9756 | AF14: 6595 | AG14: 4 | AH14: 21 | AI14: 4 | AJ14: 3 | AK14: 80 | AL14: 2 | AM14: 9 | AN14: 4 | AO14: 5 | AP14: 0 | AQ14: 0 | AR14: 3 | AS14: 36-45 | AT14: Mid Career | AU14: 19-21% | AV14: 3-5 Years
A15: No | B15: Travel_Rarely | C15: Over 55 | D15: Current Employees | E15: HR | F15: Human Resources | G15: STAFF-1973 | H15: 1973 | I15: Male | J15: Manager | K15: Married | L15: Yes | M15: Y | N15: 0 | O15: -2 | P15: 0 | Q15: 55 | R15: 0 | T15: 0 | U15: 1 | V15: 189 | W15: 26 | X15: Master's Degree | Y15: 1 | Z15: 3 | AA15: 71 | AB15: 4 | AC15: 5 | AD15: 2 | AE15: 19636 | AF15: 25811 | AG15: 4 | AH15: 18 | AI15: 3 | AJ15: 1 | AK15: 80 | AL15: 1 | AM15: 35 | AN15: 3 | AO15: 10 | AP15: 9 | AQ15: 1 | AR15: 4 | AS15: 46+ | AT15: Senior | AU15: 16-18% | AV15: 9-11 Years
A16: No | B16: Travel_Frequently | C16: 35 - 44 | D16: Current Employees | E16: HR | F16: Other | G16: STAFF-1972 | H16: 1972 | I16: Male | J16: Human Resources | K16: Married | L16: Yes | M16: Y | N16: 2 | O16: -2 | P16: 0 | Q16: 38 | R16: 0 | T16: 0 | U16: 1 | V16: 1444 | W16: 1 | X16: Master's Degree | Y16: 1 | Z16: 4 | AA16: 88 | AB16: 3 | AC16: 1 | AD16: 2 | AE16: 2991 | AF16: 5224 | AG16: 0 | AH16: 11 | AI16: 3 | AJ16: 2 | AK16: 80 | AL16: 1 | AM16: 7 | AN16: 3 | AO16: 6 | AP16: 2 | AQ16: 1 | AR16: 2 | AS16: 36-45 | AT16: Mid Career | AU16: 10-12% | AV16: 6-8 Years
A17: No | B17: Travel_Frequently | C17: 35 - 44 | D17: Current Employees | E17: HR | F17: Human Resources | G17: STAFF-1642 | H17: 1642 | I17: Male | J17: Human Resources | K17: Married | L17: Yes | M17: Y | N17: 3 | O17: -2 | P17: 0 | Q17: 44 | R17: 0 | T17: 0 | U17: 1 | V17: 602 | W17: 1 | X17: Doctoral Degree | Y17: 1 | Z17: 1 | AA17: 37 | AB17: 3 | AC17: 2 | AD17: 4 | AE17: 5743 | AF17: 10503 | AG17: 4 | AH17: 11 | AI17: 3 | AJ17: 3 | AK17: 80 | AL17: 0 | AM17: 14 | AN17: 3 | AO17: 10 | AP17: 7 | AQ17: 0 | AR17: 2 | AS17: 36-45 | AT17: Mid Career | AU17: 10-12% | AV17: 9-11 Years
A18: No | B18: Travel_Rarely | C18: 35 - 44 | D18: Current Employees | E18: HR | F18: Life Sciences | G18: STAFF-2040 | H18: 2040 | I18: Female | J18: Human Resources | K18: Single | L18: Yes | M18: Y | N18: 2 | O18: -2 | P18: 0 | Q18: 35 | R18: 0 | T18: 0 | U18: 1 | V18: 1146 | W18: 26 | X18: Master's Degree | Y18: 1 | Z18: 3 | AA18: 31 | AB18: 3 | AC18: 3 | AD18: 4 | AE18: 8837 | AF18: 16642 | AG18: 1 | AH18: 16 | AI18: 3 | AJ18: 3 | AK18: 80 | AL18: 0 | AM18: 9 | AN18: 3 | AO18: 9 | AP18: 0 | AQ18: 1 | AR18: 7 | AS18: 26-35 | AT18: Early Career | AU18: 16-18% | AV18: 9-11 Years
A19: No | B19: Travel_Rarely | C19: 35 - 44 | D19: Current Employees | E19: HR | F19: Life Sciences | G19: STAFF-1683 | H19: 1683 | I19: Female | J19: Human Resources | K19: Divorced | L19: Yes | M19: Y | N19: 2 | O19: -2 | P19: 0 | Q19: 44 | R19: 0 | T19: 0 | U19: 1 | V19: 528 | W19: 1 | X19: Bachelor's Degree | Y19: 1 | Z19: 3 | AA19: 44 | AB19: 3 | AC19: 1 | AD19: 4 | AE19: 3195 | AF19: 4167 | AG19: 4 | AH19: 18 | AI19: 3 | AJ19: 1 | AK19: 80 | AL19: 3 | AM19: 8 | AN19: 3 | AO19: 2 | AP19: 2 | AQ19: 2 | AR19: 2 | AS19: 36-45 | AT19: Mid Career | AU19: 16-18% | AV19: 0-2 Years
A20: No | B20: Travel_Rarely | C20: 35 - 44 | D20: Current Employees | E20: HR | F20: Life Sciences | G20: STAFF-1778 | H20: 1778 | I20: Male | J20: Human Resources | K20: Single | L20: No | M20: Y | N20: 5 | O20: -2 | P20: 0 | Q20: 43 | R20: 0 | T20: 0 | U20: 1 | V20: 244 | W20: 2 | X20: Bachelor's Degree | Y20: 1 | Z20: 2 | AA20: 97 | AB20: 3 | AC20: 1 | AD20: 4 | AE20: 3539 | AF20: 5033 | AG20: 0 | AH20: 13 | AI20: 3 | AJ20: 2 | AK20: 80 | AL20: 0 | AM20: 10 | AN20: 3 | AO20: 9 | AP20: 7 | AQ20: 1 | AR20: 8 | AS20: 36-45 | AT20: Mid Career | AU20: 13-15% | AV20: 9-11 Years
A21: No | B21: Travel_Rarely | C21: 25 - 34 | D21: Current Employees | E21: HR | F21: Other | G21: STAFF-1419 | H21: 1419 | I21: Male | J21: Human Resources | K21: Single | L21: No | M21: Y | N21: 3 | O21: -2 | P21: 0 | Q21: 29 | R21: 0 | T21: 0 | U21: 1 | V21: 332 | W21: 17 | X21: Bachelor's Degree | Y21: 1 | Z21: 2 | AA21: 51 | AB21: 2 | AC21: 3 | AD21: 3 | AE21: 7988 | AF21: 9769 | AG21: 1 | AH21: 13 | AI21: 3 | AJ21: 1 | AK21: 80 | AL21: 0 | AM21: 10 | AN21: 2 | AO21: 10 | AP21: 9 | AQ21: 0 | AR21: 9 | AS21: 26-35 | AT21: Early Career | AU21: 13-15% | AV21: 9-11 Years
A22: No | B22: Travel_Rarely | C22: 25 - 34 | D22: Current Employees | E22: HR | F22: Medical | G22: STAFF-1865 | H22: 1865 | I22: Male | J22: Human Resources | K22: Married | L22: No | M22: Y | N22: 3 | O22: -2 | P22: 0 | Q22: 29 | R22: 0 | T22: 0 | U22: 1 | V22: 352 | W22: 6 | X22: High School | Y22: 1 | Z22: 4 | AA22: 87 | AB22: 2 | AC22: 1 | AD22: 2 | AE22: 2804 | AF22: 15434 | AG22: 1 | AH22: 11 | AI22: 3 | AJ22: 4 | AK22: 80 | AL22: 0 | AM22: 1 | AN22: 3 | AO22: 1 | AP22: 0 | AQ22: 0 | AR22: 0 | AS22: 26-35 | AT22: Early Career | AU22: 10-12% | AV22: 0-2 Years
... A40: No | B40: Travel_Rarely | C40: 35 - 44 | D40: Current Employees | E40: HR | F40: Human Resources | G40: STAFF-1152 | H40: 1152 | I40: Male | J40: Human Resources | K40: Married | L40: No | M40: Y | N40: 2 | O40: -2 | P40: 0 | Q40: 38 | R40: 0 | T40: 0 | U40: 1 | V40: 433 | W40: 1 | X40: Bachelor's Degree | Y40: 1 | Z40: 3 | AA40: 37 | AB40: 4 | AC40: 1 | AD40: 3 | AE40: 2844 | AF40: 6004 | AG40: 1 | AH40: 13 | AI40: 3 | AJ40: 4 | AK40: 80 | AL40: 1 | AM40: 7 | AN40: 4 | AO40: 7 | AP40: 6 | AQ40: 5 | AR40: 0 | AS40: 36-45 | AT40: Mid Career | AU40: 13-15% | AV40: 6-8 Years
A41: Yes | B41: Travel_Rarely | C41: 35 - 44 | D41: Ex-Employees | E41: HR | F41: Medical | G41: STAFF-1098 | H41: 1098 | I41: Male | J41: Human Resources | K41: Married | L41: No | M41: Y | N41: 1 | O41: -2 | P41: 0 | Q41: 44 | R41: 1 | S41: 1 | T41: 1 | U41: 0 | V41: 1376 | W41: 1 | X41: Associates Degree | Y41: 1 | Z41: 2 | AA41: 91 | AB41: 2 | AC41: 3 | AD41: 3 | AE41: 10482 | AF41: 2326 | AG41: 9 | AH41: 14 | AI41: 3 | AJ41: 4 | AK41: 80 | AL41: 1 | AM41: 24 | AN41: 3 | AO41: 20 | AP41: 6 | AQ41: 3 | AR41: 6 | AS41: 36-45 | AT41: Mid Career | AU41: 13-15% | AV41: 12+ Years
A42: No | B42: Travel_Rarely | C42: 45 - 54 | D42: Current Employees | E42: HR | F42: Medical | G42: STAFF-1049 | H42: 1049 | I42: Male | J42: Human Resources | K42: Single | L42: No | M42: Y | N42: 3 | O42: -2 | P42: 0 | Q42: 45 | R42: 0 | T42: 0 | U42: 1 | V42: 788 | W42: 24 | X42: Master's Degree | Y42: 1 | Z42: 2 | AA42: 36 | AB42: 3 | AC42: 1 | AD42: 3 | AE42: 2177 | AF42: 8318 | AG42: 1 | AH42: 16 | AI42: 3 | AJ42: 1 | AK42: 80 | AL42: 0 | AM42: 6 | AN42: 3 | AO42: 6 | AP42: 3 | AQ42: 0 | AR42: 4 | AS42: 36-45 | AT42: Mid Career | AU42: 16-18% | AV42: 6-8 Years
A43: No | B43: Travel_Rarely | C43: 25 - 34 | D43: Current Employees | E43: HR | F43: Human Resources | G43: STAFF-910 | H43: 910 | I43: Male | J43: Human Resources | K43: Divorced | L43: Yes | M43: Y | N43: 4 | O43: -2 | P43: 0 | Q43: 33 | R43: 0 | T43: 0 | U43: 1 | V43: 1075 | W43: 3 | X43: Associates Degree | Y43: 1 | Z43: 4 | AA43: 57 | AB43: 3 | AC43: 1 | AD43: 3 | AE43: 2277 | AF43: 22650 | AG43: 3 | AH43: 11 | AI43: 3 | AJ43: 3 | AK43: 80 | AL43: 1 | AM43: 7 | AN43: 4 | AO43: 4 | AP43: 3 | AQ43: 0 | AR43: 3 | AS43: 26-35 | AT43: Early Career | AU43: 10-12% | AV43: 3-5 Years
A44: No | B44: Travel_Rarely | C44: 35 - 44 | D44: Current Employees | E44: HR | F44: Life Sciences | G44: STAFF-909 | H44: 909 | I44: Female | J44: Human Resources | K44: Married | L44: No | M44: Y | N44: 2 | O44: -2 | P44: 0 | Q44: 39 | R44: 0 | T44: 0 | U44: 1 | V44: 1383 | W44: 2 | X44: Bachelor's Degree | Y44: 1 | Z44: 4 | AA44: 42 | AB44: 2 | AC44: 2 | AD44: 1 | AE44: 5204 | AF44: 7790 | AG44: 8 | AH44: 11 | AI44: 3 | AJ44: 3 | AK44: 80 | AL44: 2 | AM44: 13 | AN44: 3 | AO44: 5 | AP44: 4 | AQ44: 0 | AR44: 4 | AS44: 36-45 | AT44: Mid Career | AU44: 10-12% | AV44: 3-5 Years
A45: No | B45: Travel_Rarely | C45: 35 - 44 | D45: Current Employees | E45: HR | F45: Life Sciences | G45: STAFF-878 | H45: 878 | I45: Male | J45: Human Resources | K45: Married | L45: No | M45: Y | N45: 3 | O45: -2 | P45: 0 | Q45: 36 | R45: 0 | T45: 0 | U45: 1 | V45: 1278 | W45: 8 | X45: Bachelor's Degree | Y45: 1 | Z45: 1 | AA45: 77 | AB45: 2 | AC45: 1 | AD45: 1 | AE45: 2342 | AF45: 8635 | AG45: 0 | AH45: 21 | AI45: 4 | AJ45: 3 | AK45: 80 | AL45: 0 | AM45: 6 | AN45: 3 | AO45: 5 | AP45: 4 | AQ45: 0 | AR45: 3 | AS45: 36-45 | AT45: Mid Career | AU45: 19-21% | AV45: 3-5 Years
A46: No | B46: Travel_Rarely | C46: 25 - 34 | D46: Current Employees | E46: HR | F46: Medical | G46: STAFF-869 | H46: 869 | I46: Male | J46: Human Resources | K46: Divorced | L46: No | M46: Y | N46: 6 | O46: -2 | P46: 0 | Q46: 28 | R46: 0 | T46: 0 | U46: 1 | V46: 1169 | W46: 8 | X46: Associates Degree | Y46: 1 | Z46: 2 | AA46: 63 | AB46: 2 | AC46: 1 | AD46: 4 | AE46: 4936 | AF46: 23965 | AG46: 1 | AH46: 13 | AI46: 3 | AJ46: 4 | AK46: 80 | AL46: 1 | AM46: 6 | AN46: 3 | AO46: 5 | AP46: 1 | AQ46: 0 | AR46: 4 | AS46: 26-35 | AT46: Early Career | AU46: 13-15% | AV46: 3-5 Years
A47: No | B47: Travel_Rarely | C47: 25 - 34 | D47: Current Employees | E47: HR | F47: Human Resources | G47: STAFF-847 | H47: 847 | I47: Male | J47: Human Resources | K47: Married | L47: No | M47: Y | N47: 1 | O47: -2 | P47: 0 | Q47: 34 | R47: 0 | T47: 0 | U47: 1 | V47: 829 | W47: 3 | X47: Associates Degree | Y47: 1 | Z47: 3 | AA47: 88 | AB47: 3 | AC47: 1 | AD47: 4 | AE47: 3737 | AF47: 2243 | AG47: 0 | AH47: 19 | AI47: 3 | AJ47: 3 | AK47: 80 | AL47: 1 | AM47: 4 | AN47: 1 | AO47: 3 | AP47: 2 | AQ47: 0 | AR47: 2 | AS47: 26-35 | AT47: Early Career | AU47: 19-21% | AV47: 3-5 Years
A48: No | B48: Travel_Rarely | C48: 35 - 44 | D48: Current Employees | E48: HR | F48: Human Resources | G48: STAFF-829 | H48: 829 | I48: Male | J48: Human Resources | K48: Married | L48: No | M48: Y | N48: 2 | O48: -2 | P48: 0 | Q48: 36 | R48: 0 | T48: 0 | U48: 1 | V48: 1041 | W48: 13 | X48: Bachelor's Degree | Y48: 1 | Z48: 3 | AA48: 36 | AB48: 3 | AC48: 1 | AD48: 3 | AE48: 2143 | AF48: 25527 | AG48: 4 | AH48: 13 | AI48: 3 | AJ48: 2 | AK48: 80 | AL48: 1 | AM48: 8 | AN48: 3 | AO48: 5 | AP48: 2 | AQ48: 0 | AR48: 4 | AS48: 36-45 | AT48: Mid Career | AU48: 13-15% | AV48: 3-5 Years
A49: No | B49: Travel_Rarely | C49: 35 - 44 | D49: Current Employees | E49: HR | F49: Human Resources | G49: STAFF-760 | H49: 760 | I49: Female | J49: Human Resources | K49: Married | L49: No | M49: Y | N49: 3 | O49: -2 | P49: 0 | Q49: 39 | R49: 0 | T49: 0 | U49: 1 | V49: 141 | W49: 3 | X49: Bachelor's Degree | Y49: 1 | Z49: 3 | AA49: 44 | AB49: 4 | AC49: 2 | AD49: 3 | AE49: 6389 | AF49: 18767 | AG49: 9 | AH49: 15 | AI49: 3 | AJ49: 3 | AK49: 80 | AL49: 1 | AM49: 12 | AN49: 1 | AO49: 8 | AP49: 3 | AQ49: 3 | AR49: 6 | AS49: 36-45 | AT49: Mid Career | AU49: 13-15% | AV49: 6-8 Years
A50: No | B50: Travel_Rarely | C50: 35 - 44 | D50: Current Employees | E50: HR | F50: Human Resources | G50: STAFF-734 | H50: 734 | I50: Male | J50: Manager | K50: Married | L50: No | M50: Y | N50: 3 | O50: -2 | P50: 0 | Q50: 41 | R50: 0 | T50: 0 | U50: 1 | V50: 314 | W50: 1 | X50: Bachelor's Degree | Y50: 1 | Z50: 4 | AA50: 59 | AB50: 2 | AC50: 5 | AD50: 3 | AE50: 19189 | AF50: 19562 | AG50: 1 | AH50: 12 | AI50: 3 | AJ50: 2 | AK50: 80 | AL50: 1 | AM50: 22 | AN50: 3 | AO50: 22 | AP50: 7 | AQ50: 2 | AR50: 10 | AS50: 36-45 | AT50: Mid Career | AU50: 10-12% | AV50: 12+ Years
A51: No | B51: Travel_Rarely | C51: 35 - 44 | D51: Current Employees | E51: HR | F51: Human Resources | G51: STAFF-731 | H51: 731 | I51: Male | J51: Manager | K51: Divorced | L51: No | M51: Y | N51: 2 | O51: -2 | P51: 0 | Q51: 41 | R51: 0 | T51: 0 | U51: 1 | V51: 427 | W51: 10 | X51: Master's Degree | Y51: 1 | Z51: 2 | AA51: 73 | AB51: 2 | AC51: 5 | AD51: 4 | AE51: 19141 | AF51: 8861 | AG51: 3 | AH51: 15 | AI51: 3 | AJ51: 2 | AK51: 80 | AL51: 3 | AM51: 23 | AN51: 2 | AO51: 21 | AP51: 6 | AQ51: 12 | AR51: 6 | AS51: 36-45 | AT51: Mid Career | AU51: 13-15% | AV51: 12+ Years
A52: No | B52: Travel_Rarely | C52: 45 - 54 | D52: Current Employees | E52: HR | F52: Medical | G52: STAFF-698 | H52: 698 | I52: Male | J52: Human Resources | K52: Married | L52: No | M52: Y | N52: 1 | O52: -2 | P52: 0 | Q52: 54 | R52: 0 | T52: 0 | U52: 1 | V52: 397 | W52: 19 | X52: Master's Degree | Y52: 1 | Z52: 3 | AA52: 88 | AB52: 3 | AC52: 3 | AD52: 3 | AE52: 10725 | AF52: 6729 | AG52: 2 | AH52: 15 | AI52: 3 | AJ52: 3 | AK52: 80 | AL52: 1 | AM52: 16 | AN52: 4 | AO52: 9 | AP52: 7 | AQ52: 7 | AR52: 1 | AS52: 46+ | AT52: Senior | AU52: 13-15% | AV52: 9-11 Years
A53: No | B53: Travel_Rarely | C53: 35 - 44 | D53: Current Employees | E53: HR | F53: Life Sciences | G53: STAFF-665 | H53: 665 | I53: Female | J53: Human Resources | K53: Single | L53: No | M53: Y | N53: 1 | O53: -2 | P53: 0 | Q53: 44 | R53: 0 | T53: 0 | U53: 1 | V53: 1112 | W53: 1 | X53: Master's Degree | Y53: 1 | Z53: 1 | AA53: 50 | AB53: 2 | AC53: 2 | AD53: 2 | AE53: 5985 | AF53: 26894 | AG53: 4 | AH53: 11 | AI53: 3 | AJ53: 2 | AK53: 80 | AL53: 0 | AM53: 10 | AN53: 4 | AO53: 2 | AP53: 2 | AQ53: 0 | AR53: 2 | AS53: 36-45 | AT53: Mid Career | AU53: 10-12% | AV53: 0-2 Years
A54: No | B54: Travel_Frequently | C54: 45 - 54 | D54: Current Employees | E54: HR | F54: Medical | G54: STAFF-644 | H54: 644 | I54: Male | J54: Manager | K54: Married | L54: No | M54: Y | N54: 2 | O54: -2 | P54: 0 | Q54: 50 | R54: 0 | T54: 0 | U54: 1 | V54: 1246 | W54: 3 | X54: Bachelor's Degree | Y54: 1 | Z54: 1 | AA54: 99 | AB54: 3 | AC54: 5 | AD54: 3 | AE54: 18200 | AF54: 7999 | AG54: 1 | AH54: 11 | AI54: 3 | AJ54: 3 | AK54: 80 | AL54: 1 | AM54: 32 | AN54: 3 | AO54: 32 | AP54: 5 | AQ54: 10 | AR54: 7 | AS54: 46+ | AT54: Senior | AU54: 10-12% | AV54: 12+ Years
A55: Yes | B55: Travel_Frequently | C55: 25 - 34 | D55: Ex-Employees | E55: HR | F55: Life Sciences | G55: STAFF-608 | H55: 608 | I55: Female | J55: Human Resources | K55: Divorced | L55: Yes | M55: Y | N55: 2 | O55: -2 | P55: 0 | Q55: 26 | R55: 1 | S55: 1 | T55: 1 | U55: 0 | V55: 426 | W55: 17 | X55: Master's Degree | Y55: 1 | Z55: 2 | AA55: 58 | AB55: 3 | AC55: 1 | AD55: 2 | AE55: 2741 | AF55: 22808 | AG55: 0 | AH55: 11 | AI55: 3 | AJ55: 2 | AK55: 80 | AL55: 1 | AM55: 8 | AN55: 2 | AO55: 7 | AP55: 7 | AQ55: 1 | AR55: 0 | AS55: 26-35 | AT55: Early Career | AU55: 10-12% | AV55: 6-8 Years
A56: Yes | B56: Travel_Frequently | C56: 25 - 34 | D56: Ex-Employees | E56: HR | F56: Human Resources | G56: STAFF-590 | H56: 590 | I56: Female | J56: Human Resources | K56: Divorced | L56: Yes | M56: Y | N56: 2 | O56: -2 | P56: 0 | Q56: 34 | R56: 1 | S56: 1 | T56: 1 | U56: 0 | V56: 988 | W56: 23 | X56: Bachelor's Degree | Y56: 1 | Z56: 2 | AA56: 43 | AB56: 3 | AC56: 3 | AD56: 3 | AE56: 9950 | AF56: 11533 | AG56: 9 | AH56: 15 | AI56: 3 | AJ56: 3 | AK56: 80 | AL56: 3 | AM56: 11 | AN56: 3 | AO56: 3 | AP56: 2 | AQ56: 0 | AR56: 2 | AS56: 26-35 | AT56: Early Career | AU56: 13-15% | AV56: 3-5 Years
A57: Yes | B57: Travel_Rarely | C57: Under 25 | D57: Ex-Employees | E57: HR | F57: Technical Degree | G57: STAFF-566 | H57: 566 | I57: Male | J57: Human Resources | K57: Single | L57: No | M57: Y | N57: 3 | O57: -2 | P57: 0 | Q57: 19 | R57: 1 | S57: 1 | T57: 1 | U57: 0 | V57: 489 | W57: 2 | X57: Associates Degree | Y57: 1 | Z57: 4 | AA57: 52 | AB57: 2 | AC57: 1 | AD57: 4 | AE57: 2564 | AF57: 18437 | AG57: 1 | AH57: 12 | AI57: 3 | AJ57: 3 | AK57: 80 | AL57: 0 | AM57: 1 | AN57: 4 | AO57: 1 | AP57: 0 | AQ57: 0 | AR57: 0 | AS57: 18-25 | AT57: Young | AU57: 10-12% | AV57: 0-2 Years
A58: No | B58: Travel_Rarely | C58: 35 - 44 | D58: Current Employees | E58: HR | F58: Technical Degree | G58: STAFF-470 | H58: 470 | I58: Male | J58: Human Resources | K58: Divorced | L58: Yes | M58: Y | N58: 5 | O58: -2 | P58: 0 | Q58: 42 | R58: 0 | T58: 0 | U58: 1 | V58: 544 | W58: 2 | X58: High School | Y58: 1 | Z58: 4 | AA58: 52 | AB58: 3 | AC58: 1 | AD58: 4 | AE58: 2696 | AF58: 24017 | AG58: 0 | AH58: 11 | AI58: 3 | AJ58: 3 | AK58: 80 | AL58: 1 | AM58: 4 | AN58: 3 | AO58: 3 | AP58: 2 | AQ58: 1 | AR58: 0 | AS58: 36-45 | AT58: Mid Career | AU58: 10-12% | AV58: 3-5 Years
...

Sheet Attrition Contribution by Depar
A3: Row Labels | B3: Sum of CF_attrition count
A4: HR | B4: 0.050632911
A5: Sales | B5: 0.38818565
A6: R&D | B6: 0.56118143
A7: Grand Total | B7: 1

Sheet Attrition By Job
A3: Row Labels | B3: Sum of CF_attrition counts | E3: Row Labels | F3: Sum of CF_attrition counts
A4: Laboratory Technician | B4: 62 | E4: =A4 -> Laboratory Technician | F4: =B4 -> 62
A5: Sales Executive | B5: 57 | E5: =A5 -> Sales Executive | F5: =B5 -> 57
A6: Research Scientist | B6: 47 | E6: =A6 -> Research Scientist | F6: =B6 -> 47
A7: Sales Representative | B7: 33 | E7: =A7 -> Sales Representative | F7: =B7 -> 33
A8: Human Resources | B8: 12 | E8: =A8 -> Human Resources | F8: =B8 -> 12
A9: Manufacturing Director | B9: 10 | E9: =A9 -> Manufacturing Director | F9: =B9 -> 10
A10: Healthcare Representative | B10: 9 | E10: =A10 -> Healthcare Representative | F10: =B10 -> 9
A11: Manager | B11: 5 | E11: =A11 -> Manager | F11: =B11 -> 5
A12: Research Director | B12: 2 | E12: =A12 -> Research Director | F12: =B12 -> 2
A13: Grand Total | B13: 237

Sheet Attrition vs years at company
A3: Row Labels | B3: Sum of CF_attrition count
A4: 0 | B4: 16
A5: 1 | B5: 59
A6: 2 | B6: 27
A7: 3 | B7: 20
A8: 4 | B8: 19
A9: 5 | B9: 21
A10: 6 | B10: 9
A11: 7 | B11: 11
A12: 8 | B12: 9
A13: 9 | B13: 8
A14: 10 | B14: 18
A15: 11 | B15: 2
... A40: 40 | B40: 1
A41: Grand Total | B41: 237

Sheet Attrition by age group
A3: Row Labels | B3: Sum of CF_attrition count
A4: 25 - 34 | B4: 112
A5: 35 - 44 | B5: 51
A6: Under 25 | B6: 38
A7: 45 - 54 | B7: 25
A8: Over 55 | B8: 11
A9: Grand Total | B9: 237

Sheet Education wise Attrition
A3: Row Labels | B3: Sum of CF_attrition count
A4: Bachelor's Degree | B4: 99
A5: Master's Degree | B5: 58
A6: Associates Degree | B6: 44
A7: High School | B7: 31
A8: Doctoral Degree | B8: 5
A9: Grand Total | B9: 237

Sheet Marital Status
A3: Row Labels | B3: Count of Attrition | D3: Marital Status | E3: Attrition
A4: Divorced | B4: 327 | D4: =A4 -> Divorced | E4: =B4 -> 327
A5: Single | B5: 470 | D5: =A5 -> Single | E5: =B5 -> 470
A6: Married | B6: 673 | D6: =A6 -> Married | E6: =B6 -> 673
A7: Grand Total | B7: 1470

Sheet Salary_hiks vs attrition
B3: Sum of CF_attrition count
A4: 10-12% | B4: 74
A5: 13-15% | B5: 76
A6: 16-18% | B6: 41
A7: 19-21% | B7: 21
A8: 22%+ | B8: 25
A9: Grand Total | B9: 237

Sheet Attrition by years at company
A3: Row Labels | B3: Sum of CF_attrition count
A4: 0-2 Years | B4: 102
A5: 3-5 Years | B5: 60
A6: 6-8 Years | B6: 29
A7: 9-11 Years | B7: 28
A8: 12+ Years | B8: 18
A9: Grand Total | B9: 237

Sheet Data
A1: Attrition | B1: Business Travel | C1: CF_age band | D1: CF_attrition label | E1: Department | F1: Education Field | G1: emp no | H1: Employee Number | I1: Gender | J1: Job Role | K1: Marital Status | L1: Over Time | M1: Over18 | N1: Training Times Last Year | O1: -2 | P1: 0 | Q1: Age | R1: CF_attrition count | S1: CF_attrition counts | T1: CF_attrition rate | U1: CF_current Employee | V1: Daily Rate | W1: Distance From Home | X1: Education | Y1: Employee Count | Z1: Environment Satisfaction | AA1: Hourly Rate | AB1: Job Involvement | AC1: Job Level | AD1: Job Satisfaction | AE1: Monthly Income | AF1: Monthly Rate | AG1: Num Companies Worked | AH1: Percent Salary Hike | AI1: Performance Rating | AJ1: Relationship Satisfaction | AK1: Standard Hours | AL1: Stock Option Level | AM1: Total Working Years | AN1: Work Life Balance | AO1: Years At Company | AP1: Years In Current Role | AQ1: Years Since Last Promotion | AR1: Years With Curr Manager | AS1: Age Group | AT1: Group | AU1: Salary_Hike_Group | AV1: Years_in_company_group
A2: Yes | B2: Travel_Rarely | C2: 35 - 44 | D2: Ex-Employees | E2: Sales | F2: Life Sciences | G2: STAFF-1 | H2: 1 | I2: Female | J2: Sales Executive | K2: Single | L2: Yes | M2: Y | N2: 0 | O2: -2 | P2: 0 | Q2: 41 | R2: 1 | S2: 1 | T2: 1 | U2: 0 | V2: 1102 | W2: 1 | X2: Associates Degree | Y2: 1 | Z2: 2 | AA2: 94 | AB2: 3 | AC2: 2 | AD2: 4 | AE2: 5993 | AF2: 19479 | AG2: 8 | AH2: 11 | AI2: 3 | AJ2: 1 | AK2: 80 | AL2: 0 | AM2: 8 | AN2: 1 | AO2: 6 | AP2: 4 | AQ2: 0 | AR2: 5 | AS2: =IF(Data!Q2<=25,"18-25",IF(Data!Q2<=35,"26-35",IF(Data!Q2<=45,"36-45","46+"))) -> 36-45 | AT2: =IF(AS2="18-25","Young",IF(AS2="26-35","Early Career",IF(AS2="36-45","Mid Career","Senior"))) -> Mid Career | AU2: =IF(Table_1[[#This Row],[Percent Salary Hike]]<=12,"10-12%",IF(Table_1[[#This Row],[Percent Salary Hike]]<=15,"13-15%",IF(Table_1[[#This Row],[Percent Salary Hike]]<=18,"16-18%",IF(Table_1[[#This Row],[Percent Salary Hike]]<=21,"19-21%","22%+")))) -> 10-12% | AV2: =IF(Table_1[[#This Row],[Years At Company]]<=2,"0-2 Years",IF(Table_1[[#This Row],[Years At Company]]<=5,"3-5 Years",IF(Table_1[[#This Row],[Years At Company]]<=8,"6-8 Years",IF(Table_1[[#This Row],[Years At Company]]<=11,"9-11 Years","12+ Years")))) -> 6-8 Years
A3: No | B3: Travel_Frequently | C3: 45 - 54 | D3: Current Employees | E3: R&D | F3: Life Sciences | G3: STAFF-2 | H3: 2 | I3: Male | J3: Research Scientist | K3: Married | L3: No | M3: Y | N3: 3 | O3: -2 | P3: 0 | Q3: 49 | R3: 0 | T3: 0 | U3: 1 | V3: 279 | W3: 8 | X3: High School | Y3: 1 | Z3: 3 | AA3: 61 | AB3: 2 | AC3: 2 | AD3: 2 | AE3: 5130 | AF3: 24907 | AG3: 1 | AH3: 23 | AI3: 4 | AJ3: 4 | AK3: 80 | AL3: 1 | AM3: 10 | AN3: 3 | AO3: 10 | AP3: 7 | AQ3: 1 | AR3: 7 | AS3: =IF(Data!Q3<=25,"18-25",IF(Data!Q3<=35,"26-35",IF(Data!Q3<=45,"36-45","46+"))) -> 46+ | AT3: =IF(AS3="18-25","Young",IF(AS3="26-35","Early Career",IF(AS3="36-45","Mid Career","Senior"))) -> Senior | AU3: =IF(Table_1[[#This Row],[Percent Salary Hike]]<=12,"10-12%",IF(Table_1[[#This Row],[Percent Salary Hike]]<=15,"13-15%",IF(Table_1[[#This Row],[Percent Salary Hike]]<=18,"16-18%",IF(Table_1[[#This Row],[Percent Salary Hike]]<=21,"19-21%","22%+")))) -> 22%+ | AV3: =IF(Table_1[[#This Row],[Years At Company]]<=2,"0-2 Years",IF(Table_1[[#This Row],[Years At Company]]<=5,"3-5 Years",IF(Table_1[[#This Row],[Years At Company]]<=8,"6-8 Years",IF(Table_1[[#This Row],[Years At Company]]<=11,"9-11 Years","12+ Years")))) -> 9-11 Years
A4: Yes | B4: Travel_Rarely | C4: 35 - 44 | D4: Ex-Employees | E4: R&D | F4: Other | G4: STAFF-4 | H4: 4 | I4: Male | J4: Laboratory Technician | K4: Single | L4: Yes | M4: Y | N4: 3 | O4: -2 | P4: 0 | Q4: 37 | R4: 1 | S4: 1 | T4: 1 | U4: 0 | V4: 1373 | W4: 2 | X4: Associates Degree | Y4: 1 | Z4: 4 | AA4: 92 | AB4: 2 | AC4: 1 | AD4: 3 | AE4: 2090 | AF4: 2396 | AG4: 6 | AH4: 15 | AI4: 3 | AJ4: 2 | AK4: 80 | AL4: 0 | AM4: 7 | AN4: 3 | AO4: 0 | AP4: 0 | AQ4: 0 | AR4: 0 | AS4: =IF(Data!Q4<=25,"18-25",IF(Data!Q4<=35,"26-35",IF(Data!Q4<=45,"36-45","46+"))) -> 36-45 | AT4: =IF(AS4="18-25","Young",IF(AS4="26-35","Early Career",IF(AS4="36-45","Mid Career","Senior"))) -> Mid Career | AU4: =IF(Table_1[[#This Row],[Percent Salary Hike]]<=12,"10-12%",IF(Table_1[[#This Row],[Percent Salary Hike]]<=15,"13-15%",IF(Table_1[[#This Row],[Percent Salary Hike]]<=18,"16-18%",IF(Table_1[[#This Row],[Percent Salary Hike]]<=21,"19-21%","22%+")))) -> 13-15% | AV4: =IF(Table_1[[#This Row],[Years At Company]]<=2,"0-2 Years",IF(Table_1[[#This Row],[Years At Company]]<=5,"3-5 Years",IF(Table_1[[#This Row],[Years At Company]]<=8,"6-8 Years",IF(Table_1[[#This Row],[Years At Company]]<=11,"9-11 Years","12+ Years")))) -> 0-2 Years
A5: No | B5: Travel_Frequently | C5: 25 - 34 | D5: Current Employees | E5: R&D | F5: Life Sciences | G5: STAFF-5 | H5: 5 | I5: Female | J5: Research Scientist | K5: Married | L5: Yes | M5: Y | N5: 3 | O5: -2 | P5: 0 | Q5: 33 | R5: 0 | T5: 0 | U5: 1 | V5: 1392 | W5: 3 | X5: Master's Degree | Y5: 1 | Z5: 4 | AA5: 56 | AB5: 3 | AC5: 1 | AD5: 3 | AE5: 2909 | AF5: 23159 | AG5: 1 | AH5: 11 | AI5: 3 | AJ5: 3 | AK5: 80 | AL5: 0 | AM5: 8 | AN5: 3 | AO5: 8 | AP5: 7 | AQ5: 3 | AR5: 0 | AS5: =IF(Data!Q5<=25,"18-25",IF(Data!Q5<=35,"26-35",IF(Data!Q5<=45,"36-45","46+"))) -> 26-35 | AT5: =IF(AS5="18-25","Young",IF(AS5="26-35","Early Career",IF(AS5="36-45","Mid Career","Senior"))) -> Early Career | AU5: =IF(Table_1[[#This Row],[Percent Salary Hike]]<=12,"10-12%",IF(Table_1[[#This Row],[Percent Salary Hike]]<=15,"13-15%",IF(Table_1[[#This Row],[Percent Salary Hike]]<=18,"16-18%",IF(Table_1[[#This Row],[Percent Salary Hike]]<=21,"19-21%","22%+")))) -> 10-12% | AV5: =IF(Table_1[[#This Row],[Years At Company]]<=2,"0-2 Years",IF(Table_1[[#This Row],[Years At Company]]<=5,"3-5 Years",IF(Table_1[[#This Row],[Years At Company]]<=8,"6-8 Years",IF(Table_1[[#This Row],[Years At Company]]<=11,"9-11 Years","12+ Years")))) -> 6-8 Years
A6: No | B6: Travel_Rarely | C6: 25 - 34 | D6: Current Employees | E6: R&D | F6: Medical | G6: STAFF-7 | H6: 7 | I6: Male | J6: Laboratory Technician | K6: Married | L6: No | M6: Y | N6: 3 | O6: -2 | P6: 0 | Q6: 27 | R6: 0 | T6: 0 | U6: 1 | V6: 591 | W6: 2 | X6: High School | Y6: 1 | Z6: 1 | AA6: 40 | AB6: 3 | AC6: 1 | AD6: 2 | AE6: 3468 | AF6: 16632 | AG6: 9 | AH6: 12 | AI6: 3 | AJ6: 4 | AK6: 80 | AL6: 1 | AM6: 6 | AN6: 3 | AO6: 2 | AP6: 2 | AQ6: 2 | AR6: 2 | AS6: =IF(Data!Q6<=25,"18-25",IF(Data!Q6<=35,"26-35",IF(Data!Q6<=45,"36-45","46+"))) -> 26-35 | AT6: =IF(AS6="18-25","Young",IF(AS6="26-35","Early Career",IF(AS6="36-45","Mid Career","Senior"))) -> Early Career | AU6: =IF(Table_1[[#This Row],[Percent Salary Hike]]<=12,"10-12%",IF(Table_1[[#This Row],[Percent Salary Hike]]<=15,"13-15%",IF(Table_1[[#This Row],[Percent Salary Hike]]<=18,"16-18%",IF(Table_1[[#This Row],[Percent Salary Hike]]<=21,"19-21%","22%+")))) -> 10-12% | AV6: =IF(Table_1[[#This Row],[Years At Company]]<=2,"0-2 Years",IF(Table_1[[#This Row],[Years At Company]]<=5,"3-5 Years",IF(Table_1[[#This Row],[Years At Company]]<=8,"6-8 Years",IF(Table_1[[#This Row],[Years At Company]]<=11,"9-11 Years","12+ Years")))) -> 0-2 Years
A7: No | B7: Travel_Frequently | C7: 25 - 34 | D7: Current Employees | E7: R&D | F7: Life Sciences | G7: STAFF-8 | H7: 8 | I7: Male | J7: Laboratory Technician | K7: Single | L7: No | M7: Y | N7: 2 | O7: -2 | P7: 0 | Q7: 32 | R7: 0 | T7: 0 | U7: 1 | V7: 1005 | W7: 2 | X7: Associates Degree | Y7: 1 | Z7: 4 | AA7: 79 | AB7: 3 | AC7: 1 | AD7: 2 | AE7: 3068 | AF7: 11864 | AG7: 0 | AH7: 13 | AI7: 3 | AJ7: 3 | AK7: 80 | AL7: 0 | AM7: 8 | AN7: 2 | AO7: 7 | AP7: 7 | AQ7: 3 | AR7: 6 | AS7: =IF(Data!Q7<=25,"18-25",IF(Data!Q7<=35,"26-35",IF(Data!Q7<=45,"36-45","46+"))) -> 26-35 | AT7: =IF(AS7="18-25","Young",IF(AS7="26-35","Early Career",IF(AS7="36-45","Mid Career","Senior"))) -> Early Career | AU7: =IF(Table_1[[#This Row],[Percent Salary Hike]]<=12,"10-12%",IF(Table_1[[#This Row],[Percent Salary Hike]]<=15,"13-15%",IF(Table_1[[#This Row],[Percent Salary Hike]]<=18,"16-18%",IF(Table_1[[#This Row],[Percent Salary Hike]]<=21,"19-21%","22%+")))) -> 13-15% | AV7: =IF(Table_1[[#This Row],[Years At Company]]<=2,"0-2 Years",IF(Table_1[[#This Row],[Years At Company]]<=5,"3-5 Years",IF(Table_1[[#This Row],[Years At Company]]<=8,"6-8 Years",IF(Table_1[[#This Row],[Years At Company]]<=11,"9-11 Years","12+ Years")))) -> 6-8 Years
A8: No | B8: Travel_Rarely | C8: Over 55 | D8: Current Employees | E8: R&D | F8: Medical | G8: STAFF-10 | H8: 10 | I8: Female | J8: Laboratory Technician | K8: Married | L8: Yes | M8: Y | N8: 3 | O8: -2 | P8: 0 | Q8: 59 | R8: 0 | T8: 0 | U8: 1 | V8: 1324 | W8: 3 | X8: Bachelor's Degree | Y8: 1 | Z8: 3 | AA8: 81 | AB8: 4 | AC8: 1 | AD8: 4 | AE8: 2670 | AF8: 9964 | AG8: 4 | AH8: 20 | AI8: 4 | AJ8: 1 | AK8: 80 | AL8: 3 | AM8: 12 | AN8: 2 | AO8: 1 | AP8: 0 | AQ8: 0 | AR8: 0 | AS8: =IF(Data!Q8<=25,"18-25",IF(Data!Q8<=35,"26-35",IF(Data!Q8<=45,"36-45","46+"))) -> 46+ | AT8: =IF(AS8="18-25","Young",IF(AS8="26-35","Early Career",IF(AS8="36-45","Mid Career","Senior"))) -> Senior | AU8: =IF(Table_1[[#This Row],[Percent Salary Hike]]<=12,"10-12%",IF(Table_1[[#This Row],[Percent Salary Hike]]<=15,"13-15%",IF(Table_1[[#This Row],[Percent Salary Hike]]<=18,"16-18%",IF(Table_1[[#This Row],[Percent Salary Hike]]<=21,"19-21%","22%+")))) -> 19-21% | AV8: =IF(Table_1[[#This Row],[Years At Company]]<=2,"0-2 Years",IF(Table_1[[#This Row],[Years At Company]]<=5,"3-5 Years",IF(Table_1[[#This Row],[Years At Company]]<=8,"6-8 Years",IF(Table_1[[#This Row],[Years At Company]]<=11,"9-11 Years","12+ Years")))) -> 0-2 Years
A9: No | B9: Travel_Rarely | C9: 25 - 34 | D9: Current Employees | E9: R&D | F9: Life Sciences | G9: STAFF-11 | H9: 11 | I9: Male | J9: Laboratory Technician | K9: Divorced | L9: No | M9: Y | N9: 2 | O9: -2 | P9: 0 | Q9: 30 | R9: 0 | T9: 0 | U9: 1 | V9: 1358 | W9: 24 | X9: High School | Y9: 1 | Z9: 4 | AA9: 67 | AB9: 3 | AC9: 1 | AD9: 2 | AE9: 2693 | AF9: 13335 | AG9: 1 | AH9: 22 | AI9: 4 | AJ9: 2 | AK9: 80 | AL9: 1 | AM9: 1 | AN9: 3 | AO9: 1 | AP9: 0 | AQ9: 0 | AR9: 0 | AS9: =IF(Data!Q9<=25,"18-25",IF(Data!Q9<=35,"26-35",IF(Data!Q9<=45,"36-45","46+"))) -> 26-35 | AT9: =IF(AS9="18-25","Young",IF(AS9="26-35","Early Career",IF(AS9="36-45","Mid Career","Senior"))) -> Early Career | AU9: =IF(Table_1[[#This Row],[Percent Salary Hike]]<=12,"10-12%",IF(Table_1[[#This Row],[Percent Salary Hike]]<=15,"13-15%",IF(Table_1[[#This Row],[Percent Salary Hike]]<=18,"16-18%",IF(Table_1[[#This Row],[Percent Salary Hike]]<=21,"19-21%","22%+")))) -> 22%+ | AV9: =IF(Table_1[[#This Row],[Years At Company]]<=2,"0-2 Years",IF(Table_1[[#This Row],[Years At Company]]<=5,"3-5 Years",IF(Table_1[[#This Row],[Years At Company]]<=8,"6-8 Years",IF(Table_1[[#This Row],[Years At Company]]<=11,"9-11 Years","12+ Years")))) -> 0-2 Years
A10: No | B10: Travel_Frequently | C10: 35 - 44 | D10: Current Employees | E10: R&D | F10: Life Sciences | G10: STAFF-12 | H10: 12 | I10: Male | J10: Manufacturing Director | K10: Single | L10: No | M10: Y | N10: 2 | O10: -2 | P10: 0 | Q10: 38 | R10: 0 | T10: 0 | U10: 1 | V10: 216 | W10: 23 | X10: Bachelor's Degree | Y10: 1 | Z10: 4 | AA10: 44 | AB10: 2 | AC10: 3 | AD10: 2 | AE10: 9526 | AF10: 8787 | AG10: 0 | AH10: 21 | AI10: 4 | AJ10: 2 | AK10: 80 | AL10: 0 | AM10: 10 | AN10: 3 | AO10: 9 | AP10: 7 | AQ10: 1 | AR10: 8 | AS10: =IF(Data!Q10<=25,"18-25",IF(Data!Q10<=35,"26-35",IF(Data!Q10<=45,"36-45","46+"))) -> 36-45 | AT10: =IF(AS10="18-25","Young",IF(AS10="26-35","Early Career",IF(AS10="36-45","Mid Career","Senior"))) -> Mid Career | AU10: =IF(Table_1[[#This Row],[Percent Salary Hike]]<=12,"10-12%",IF(Table_1[[#This Row],[Percent Salary Hike]]<=15,"13-15%",IF(Table_1[[#This Row],[Percent Salary Hike]]<=18,"16-18%",IF(Table_1[[#This Row],[Percent Salary Hike]]<=21,"19-21%","22%+")))) -> 19-21% | AV10: =IF(Table_1[[#This Row],[Years At Company]]<=2,"0-2 Years",IF(Table_1[[#This Row],[Years At Company]]<=5,"3-5 Years",IF(Table_1[[#This Row],[Years At Company]]<=8,"6-8 Years",IF(Table_1[[#This Row],[Years At Company]]<=11,"9-11 Years","12+ Years")))) -> 9-11 Years
A11: No | B11: Travel_Rarely | C11: 35 - 44 | D11: Current Employees | E11: R&D | F11: Medical | G11: STAFF-13 | H11: 13 | I11: Male | J11: Healthcare Representative | K11: Married | L11: No | M11: Y | N11: 3 | O11: -2 | P11: 0 | Q11: 36 | R11: 0 | T11: 0 | U11: 1 | V11: 1299 | W11: 27 | X11: Bachelor's Degree | Y11: 1 | Z11: 3 | AA11: 94 | AB11: 3 | AC11: 2 | AD11: 3 | AE11: 5237 | AF11: 16577 | AG11: 6 | AH11: 13 | AI11: 3 | AJ11: 2 | AK11: 80 | AL11: 2 | AM11: 17 | AN11: 2 | AO11: 7 | AP11: 7 | AQ11: 7 | AR11: 7 | AS11: =IF(Data!Q11<=25,"18-25",IF(Data!Q11<=35,"26-35",IF(Data!Q11<=45,"36-45","46+"))) -> 36-45 | AT11: =IF(AS11="18-25","Young",IF(AS11="26-35","Early Career",IF(AS11="36-45","Mid Career","Senior"))) -> Mid Career | AU11: =IF(Table_1[[#This Row],[Percent Salary Hike]]<=12,"10-12%",IF(Table_1[[#This Row],[Percent Salary Hike]]<=15,"13-15%",IF(Table_1[[#This Row],[Percent Salary Hike]]<=18,"16-18%",IF(Table_1[[#This Row],[Percent Salary Hike]]<=21,"19-21%","22%+")))) -> 13-15% | AV11: =IF(Table_1[[#This Row],[Years At Company]]<=2,"0-2 Years",IF(Table_1[[#This Row],[Years At Company]]<=5,"3-5 Years",IF(Table_1[[#This Row],[Years At Company]]<=8,"6-8 Years",IF(Table_1[[#This Row],[Years At Company]]<=11,"9-11 Years","12+ Years")))) -> 6-8 Years
A12: No | B12: Travel_Rarely | C12: 35 - 44 | D12: Current Employees | E12: R&D | F12: Medical | G12: STAFF-14 | H12: 14 | I12: Male | J12: Laboratory Technician | K12: Married | L12: No | M12: Y | N12: 5 | O12: -2 | P12: 0 | Q12: 35 | R12: 0 | T12: 0 | U12: 1 | V12: 809 | W12: 16 | X12: Bachelor's Degree | Y12: 1 | Z12: 1 | AA12: 84 | AB12: 4 | AC12: 1 | AD12: 2 | AE12: 2426 | AF12: 16479 | AG12: 0 | AH12: 13 | AI12: 3 | AJ12: 3 | AK12: 80 | AL12: 1 | AM12: 6 | AN12: 3 | AO12: 5 | AP12: 4 | AQ12: 0 | AR12: 3 | AS12: =IF(Data!Q12<=25,"18-25",IF(Data!Q12<=35,"26-35",IF(Data!Q12<=45,"36-45","46+"))) -> 26-35 | AT12: =IF(AS12="18-25","Young",IF(AS12="26-35","Early Career",IF(AS12="36-45","Mid Career","Senior"))) -> Early Career | AU12: =IF(Table_1[[#This Row],[Percent Salary Hike]]<=12,"10-12%",IF(Table_1[[#This Row],[Percent Salary Hike]]<=15,"13-15%",IF(Table_1[[#This Row],[Percent Salary Hike]]<=18,"16-18%",IF(Table_1[[#This Row],[Percent Salary Hike]]<=21,"19-21%","22%+")))) -> 13-15% | AV12: =IF(Table_1[[#This Row],[Years At Company]]<=2,"0-2 Years",IF(Table_1[[#This Row],[Years At Company]]<=5,"3-5 Years",IF(Table_1[[#This Row],[Years At Company]]<=8,"6-8 Years",IF(Table_1[[#This Row],[Years At Company]]<=11,"9-11 Years","12+ Years")))) -> 3-5 Years
A13: No | B13: Travel_Rarely | C13: 25 - 34 | D13: Current Employees | E13: R&D | F13: Life Sciences | G13: STAFF-15 | H13: 15 | I13: Female | J13: Laboratory Technician | K13: Single | L13: Yes | M13: Y | N13: 3 | O13: -2 | P13: 0 | Q13: 29 | R13: 0 | T13: 0 | U13: 1 | V13: 153 | W13: 15 | X13: Associates Degree | Y13: 1 | Z13: 4 | AA13: 49 | AB13: 2 | AC13: 2 | AD13: 2 | AE13: 4193 | AF13: 12682 | AG13: 0 | AH13: 12 | AI13: 3 | AJ13: 4 | AK13: 80 | AL13: 0 | AM13: 10 | AN13: 3 | AO13: 9 | AP13: 5 | AQ13: 0 | AR13: 8 | AS13: =IF(Data!Q13<=25,"18-25",IF(Data!Q13<=35,"26-35",IF(Data!Q13<=45,"36-45","46+"))) -> 26-35 | AT13: =IF(AS13="18-25","Young",IF(AS13="26-35","Early Career",IF(AS13="36-45","Mid Career","Senior"))) -> Early Career | AU13: =IF(Table_1[[#This Row],[Percent Salary Hike]]<=12,"10-12%",IF(Table_1[[#This Row],[Percent Salary Hike]]<=15,"13-15%",IF(Table_1[[#This Row],[Percent Salary Hike]]<=18,"16-18%",IF(Table_1[[#This Row],[Percent Salary Hike]]<=21,"19-21%","22%+")))) -> 10-12% | AV13: =IF(Table_1[[#This Row],[Years At Company]]<=2,"0-2 Years",IF(Table_1[[#This Row],[Years At Company]]<=5,"3-5 Years",IF(Table_1[[#This Row],[Years At Company]]<=8,"6-8 Years",IF(Table_1[[#This Row],[Years At Company]]<=11,"9-11 Years","12+ Years")))) -> 9-11 Years
A14: No | B14: Travel_Rarely | C14: 25 - 34 | D14: Current Employees | E14: R&D | F14: Life Sciences | G14: STAFF-16 | H14: 16 | I14: Male | J14: Research Scientist | K14: Divorced | L14: No | M14: Y | N14: 1 | O14: -2 | P14: 0 | Q14: 31 | R14: 0 | T14: 0 | U14: 1 | V14: 670 | W14: 26 | X14: High School | Y14: 1 | Z14: 1 | AA14: 31 | AB14: 3 | AC14: 1 | AD14: 2 | AE14: 2911 | AF14: 15170 | AG14: 1 | AH14: 17 | AI14: 3 | AJ14: 4 | AK14: 80 | AL14: 1 | AM14: 5 | AN14: 2 | AO14: 5 | AP14: 2 | AQ14: 4 | AR14: 3 | AS14: =IF(Data!Q14<=25,"18-25",IF(Data!Q14<=35,"26-35",IF(Data!Q14<=45,"36-45","46+"))) -> 26-35 | AT14: =IF(AS14="18-25","Young",IF(AS14="26-35","Early Career",IF(AS14="36-45","Mid Career","Senior"))) -> Early Career | AU14: =IF(Table_1[[#This Row],[Percent Salary Hike]]<=12,"10-12%",IF(Table_1[[#This Row],[Percent Salary Hike]]<=15,"13-15%",IF(Table_1[[#This Row],[Percent Salary Hike]]<=18,"16-18%",IF(Table_1[[#This Row],[Percent Salary Hike]]<=21,"19-21%","22%+")))) -> 16-18% | AV14: =IF(Table_1[[#This Row],[Years At Company]]<=2,"0-2 Years",IF(Table_1[[#This Row],[Years At Company]]<=5,"3-5 Years",IF(Table_1[[#This Row],[Years At Company]]<=8,"6-8 Years",IF(Table_1[[#This Row],[Years At Company]]<=11,"9-11 Years","12+ Years")))) -> 3-5 Years
A15: No | B15: Travel_Rarely | C15: 25 - 34 | D15: Current Employees | E15: R&D | F15: Medical | G15: STAFF-18 | H15: 18 | I15: Male | J15: Laboratory Technician | K15: Divorced | L15: No | M15: Y | N15: 2 | O15: -2 | P15: 0 | Q15: 34 | R15: 0 | T15: 0 | U15: 1 | V15: 1346 | W15: 19 | X15: Associates Degree | Y15: 1 | Z15: 2 | AA15: 93 | AB15: 3 | AC15: 1 | AD15: 4 | AE15: 2661 | AF15: 8758 | AG15: 0 | AH15: 11 | AI15: 3 | AJ15: 3 | AK15: 80 | AL15: 1 | AM15: 3 | AN15: 3 | AO15: 2 | AP15: 2 | AQ15: 1 | AR15: 2 | AS15: =IF(Data!Q15<=25,"18-25",IF(Data!Q15<=35,"26-35",IF(Data!Q15<=45,"36-45","46+"))) -> 26-35 | AT15: =IF(AS15="18-25","Young",IF(AS15="26-35","Early Career",IF(AS15="36-45","Mid Career","Senior"))) -> Early Career | AU15: =IF(Table_1[[#This Row],[Percent Salary Hike]]<=12,"10-12%",IF(Table_1[[#This Row],[Percent Salary Hike]]<=15,"13-15%",IF(Table_1[[#This Row],[Percent Salary Hike]]<=18,"16-18%",IF(Table_1[[#This Row],[Percent Salary Hike]]<=21,"19-21%","22%+")))) -> 10-12% | AV15: =IF(Table_1[[#This Row],[Years At Company]]<=2,"0-2 Years",IF(Table_1[[#This Row],[Years At Company]]<=5,"3-5 Years",IF(Table_1[[#This Row],[Years At Company]]<=8,"6-8 Years",IF(Table_1[[#This Row],[Years At Company]]<=11,"9-11 Years","12+ Years")))) -> 0-2 Years
A16: Yes | B16: Travel_Rarely | C16: 25 - 34 | D16: Ex-Employees | E16: R&D | F16: Life Sciences | G16: STAFF-19 | H16: 19 | I16: Male | J16: Laboratory Technician | K16: Single | L16: Yes | M16: Y | N16: 4 | O16: -2 | P16: 0 | Q16: 28 | R16: 1 | S16: 1 | T16: 1 | U16: 0 | V16: 103 | W16: 24 | X16: Bachelor's Degree | Y16: 1 | Z16: 3 | AA16: 50 | AB16: 2 | AC16: 1 | AD16: 2 | AE16: 2028 | AF16: 12947 | AG16: 5 | AH16: 14 | AI16: 3 | AJ16: 2 | AK16: 80 | AL16: 0 | AM16: 6 | AN16: 3 | AO16: 4 | AP16: 2 | AQ16: 0 | AR16: 3 | AS16: =IF(Data!Q16<=25,"18-25",IF(Data!Q16<=35,"26-35",IF(Data!Q16<=45,"36-45","46+"))) -> 26-35 | AT16: =IF(AS16="18-25","Young",IF(AS16="26-35","Early Career",IF(AS16="36-45","Mid Career","Senior"))) -> Early Career | AU16: =IF(Table_1[[#This Row],[Percent Salary Hike]]<=12,"10-12%",IF(Table_1[[#This Row],[Percent Salary Hike]]<=15,"13-15%",IF(Table_1[[#This Row],[Percent Salary Hike]]<=18,"16-18%",IF(Table_1[[#This Row],[Percent Salary Hike]]<=21,"19-21%","22%+")))) -> 13-15% | AV16: =IF(Table_1[[#This Row],[Years At Company]]<=2,"0-2 Years",IF(Table_1[[#This Row],[Years At Company]]<=5,"3-5 Years",IF(Table_1[[#This Row],[Years At Company]]<=8,"6-8 Years",IF(Table_1[[#This Row],[Years At Company]]<=11,"9-11 Years","12+ Years")))) -> 3-5 Years
A17: No | B17: Travel_Rarely | C17: 25 - 34 | D17: Current Employees | E17: R&D | F17: Life Sciences | G17: STAFF-20 | H17: 20 | I17: Female | J17: Manufacturing Director | K17: Divorced | L17: No | M17: Y | N17: 1 | O17: -2 | P17: 0 | Q17: 29 | R17: 0 | T17: 0 | U17: 1 | V17: 1389 | W17: 21 | X17: Master's Degree | Y17: 1 | Z17: 2 | AA17: 51 | AB17: 4 | AC17: 3 | AD17: 2 | AE17: 9980 | AF17: 10195 | AG17: 1 | AH17: 11 | AI17: 3 | AJ17: 3 | AK17: 80 | AL17: 1 | AM17: 10 | AN17: 3 | AO17: 10 | AP17: 9 | AQ17: 8 | AR17: 8 | AS17: =IF(Data!Q17<=25,"18-25",IF(Data!Q17<=35,"26-35",IF(Data!Q17<=45,"36-45","46+"))) -> 26-35 | AT17: =IF(AS17="18-25","Young",IF(AS17="26-35","Early Career",IF(AS17="36-45","Mid Career","Senior"))) -> Early Career | AU17: =IF(Table_1[[#This Row],[Percent Salary Hike]]<=12,"10-12%",IF(Table_1[[#This Row],[Percent Salary Hike]]<=15,"13-15%",IF(Table_1[[#This Row],[Percent Salary Hike]]<=18,"16-18%",IF(Table_1[[#This Row],[Percent Salary Hike]]<=21,"19-21%","22%+")))) -> 10-12% | AV17: =IF(Table_1[[#This Row],[Years At Company]]<=2,"0-2 Years",IF(Table_1[[#This Row],[Years At Company]]<=5,"3-5 Years",IF(Table_1[[#This Row],[Years At Company]]<=8,"6-8 Years",IF(Table_1[[#This Row],[Years At Company]]<=11,"9-11 Years","12+ Years")))) -> 9-11 Years
A18: No | B18: Travel_Rarely | C18: 25 - 34 | D18: Current Employees | E18: R&D | F18: Life Sciences | G18: STAFF-21 | H18: 21 | I18: Male | J18: Research Scientist | K18: Divorced | L18: Yes | M18: Y | N18: 5 | O18: -2 | P18: 0 | Q18: 32 | R18: 0 | T18: 0 | U18: 1 | V18: 334 | W18: 5 | X18: Associates Degree | Y18: 1 | Z18: 1 | AA18: 80 | AB18: 4 | AC18: 1 | AD18: 2 | AE18: 3298 | AF18: 15053 | AG18: 0 | AH18: 12 | AI18: 3 | AJ18: 4 | AK18: 80 | AL18: 2 | AM18: 7 | AN18: 2 | AO18: 6 | AP18: 2 | AQ18: 0 | AR18: 5 | AS18: =IF(Data!Q18<=25,"18-25",IF(Data!Q18<=35,"26-35",IF(Data!Q18<=45,"36-45","46+"))) -> 26-35 | AT18: =IF(AS18="18-25","Young",IF(AS18="26-35","Early Career",IF(AS18="36-45","Mid Career","Senior"))) -> Early Career | AU18: =IF(Table_1[[#This Row],[Percent Salary Hike]]<=12,"10-12%",IF(Table_1[[#This Row],[Percent Salary Hike]]<=15,"13-15%",IF(Table_1[[#This Row],[Percent Salary Hike]]<=18,"16-18%",IF(Table_1[[#This Row],[Percent Salary Hike]]<=21,"19-21%","22%+")))) -> 10-12% | AV18: =IF(Table_1[[#This Row],[Years At Company]]<=2,"0-2 Years",IF(Table_1[[#This Row],[Years At Company]]<=5,"3-5 Years",IF(Table_1[[#This Row],[Years At Company]]<=8,"6-8 Years",IF(Table_1[[#This Row],[Years At Company]]<=11,"9-11 Years","12+ Years")))) -> 6-8 Years
A19: No | B19: Non-Travel | C19: Under 25 | D19: Current Employees | E19: R&D | F19: Medical | G19: STAFF-22 | H19: 22 | I19: Male | J19: Laboratory Technician | K19: Divorced | L19: Yes | M19: Y | N19: 2 | O19: -2 | P19: 0 | Q19: 22 | R19: 0 | T19: 0 | U19: 1 | V19: 1123 | W19: 16 | X19: Associates Degree | Y19: 1 | Z19: 4 | AA19: 96 | AB19: 4 | AC19: 1 | AD19: 4 | AE19: 2935 | AF19: 7324 | AG19: 1 | AH19: 13 | AI19: 3 | AJ19: 2 | AK19: 80 | AL19: 2 | AM19: 1 | AN19: 2 | AO19: 1 | AP19: 0 | AQ19: 0 | AR19: 0 | AS19: =IF(Data!Q19<=25,"18-25",IF(Data!Q19<=35,"26-35",IF(Data!Q19<=45,"36-45","46+"))) -> 18-25 | AT19: =IF(AS19="18-25","Young",IF(AS19="26-35","Early Career",IF(AS19="36-45","Mid Career","Senior"))) -> Young | AU19: =IF(Table_1[[#This Row],[Percent Salary Hike]]<=12,"10-12%",IF(Table_1[[#This Row],[Percent Salary Hike]]<=15,"13-15%",IF(Table_1[[#This Row],[Percent Salary Hike]]<=18,"16-18%",IF(Table_1[[#This Row],[Percent Salary Hike]]<=21,"19-21%","22%+")))) -> 13-15% | AV19: =IF(Table_1[[#This Row],[Years At Company]]<=2,"0-2 Years",IF(Table_1[[#This Row],[Years At Company]]<=5,"3-5 Years",IF(Table_1[[#This Row],[Years At Company]]<=8,"6-8 Years",IF(Table_1[[#This Row],[Years At Company]]<=11,"9-11 Years","12+ Years")))) -> 0-2 Years
A20: No | B20: Travel_Rarely | C20: 45 - 54 | D20: Current Employees | E20: Sales | F20: Life Sciences | G20: STAFF-23 | H20: 23 | I20: Female | J20: Manager | K20: Married | L20: No | M20: Y | N20: 3 | O20: -2 | P20: 0 | Q20: 53 | R20: 0 | T20: 0 | U20: 1 | V20: 1219 | W20: 2 | X20: Master's Degree | Y20: 1 | Z20: 1 | AA20: 78 | AB20: 2 | AC20: 4 | AD20: 2 | AE20: 15427 | AF20: 22021 | AG20: 2 | AH20: 16 | AI20: 3 | AJ20: 3 | AK20: 80 | AL20: 0 | AM20: 31 | AN20: 3 | AO20: 25 | AP20: 8 | AQ20: 3 | AR20: 7 | AS20: =IF(Data!Q20<=25,"18-25",IF(Data!Q20<=35,"26-35",IF(Data!Q20<=45,"36-45","46+"))) -> 46+ | AT20: =IF(AS20="18-25","Young",IF(AS20="26-35","Early Career",IF(AS20="36-45","Mid Career","Senior"))) -> Senior | AU20: =IF(Table_1[[#This Row],[Percent Salary Hike]]<=12,"10-12%",IF(Table_1[[#This Row],[Percent Salary Hike]]<=15,"13-15%",IF(Table_1[[#This Row],[Percent Salary Hike]]<=18,"16-18%",IF(Table_1[[#This Row],[Percent Salary Hike]]<=21,"19-21%","22%+")))) -> 16-18% | AV20: =IF(Table_1[[#This Row],[Years At Company]]<=2,"0-2 Years",IF(Table_1[[#This Row],[Years At Company]]<=5,"3-5 Years",IF(Table_1[[#This Row],[Years At Company]]<=8,"6-8 Years",IF(Table_1[[#This Row],[Years At Company]]<=11,"9-11 Years","12+ Years")))) -> 12+ Years
A21: No | B21: Travel_Rarely | C21: 35 - 44 | D21: Current Employees | E21: R&D | F21: Life Sciences | G21: STAFF-24 | H21: 24 | I21: Male | J21: Research Scientist | K21: Single | L21: Yes | M21: Y | N21: 3 | O21: -2 | P21: 0 | Q21: 38 | R21: 0 | T21: 0 | U21: 1 | V21: 371 | W21: 2 | X21: Bachelor's Degree | Y21: 1 | Z21: 4 | AA21: 45 | AB21: 3 | AC21: 1 | AD21: 2 | AE21: 3944 | AF21: 4306 | AG21: 5 | AH21: 11 | AI21: 3 | AJ21: 3 | AK21: 80 | AL21: 0 | AM21: 6 | AN21: 3 | AO21: 3 | AP21: 2 | AQ21: 1 | AR21: 2 | AS21: =IF(Data!Q21<=25,"18-25",IF(Data!Q21<=35,"26-35",IF(Data!Q21<=45,"36-45","46+"))) -> 36-45 | AT21: =IF(AS21="18-25","Young",IF(AS21="26-35","Early Career",IF(AS21="36-45","Mid Career","Senior"))) -> Mid Career | AU21: =IF(Table_1[[#This Row],[Percent Salary Hike]]<=12,"10-12%",IF(Table_1[[#This Row],[Percent Salary Hike]]<=15,"13-15%",IF(Table_1[[#This Row],[Percent Salary Hike]]<=18,"16-18%",IF(Table_1[[#This Row],[Percent Salary Hike]]<=21,"19-21%","22%+")))) -> 10-12% | AV21: =IF(Table_1[[#This Row],[Years At Company]]<=2,"0-2 Years",IF(Table_1[[#This Row],[Years At Company]]<=5,"3-5 Years",IF(Table_1[[#This Row],[Years At Company]]<=8,"6-8 Years",IF(Table_1[[#This Row],[Years At Company]]<=11,"9-11 Years","12+ Years")))) -> 3-5 Years
A22: No | B22: Non-Travel | C22: Under 25 | D22: Current Employees | E22: R&D | F22: Other | G22: STAFF-26 | H22: 26 | I22: Female | J22: Manufacturing Director | K22: Divorced | L22: No | M22: Y | N22: 5 | O22: -2 | P22: 0 | Q22: 24 | R22: 0 | T22: 0 | U22: 1 | V22: 673 | W22: 11 | X22: Associates Degree | Y22: 1 | Z22: 1 | AA22: 96 | AB22: 4 | AC22: 2 | AD22: 3 | AE22: 4011 | AF22: 8232 | AG22: 0 | AH22: 18 | AI22: 3 | AJ22: 4 | AK22: 80 | AL22: 1 | AM22: 5 | AN22: 2 | AO22: 4 | AP22: 2 | AQ22: 1 | AR22: 3 | AS22: =IF(Data!Q22<=25,"18-25",IF(Data!Q22<=35,"26-35",IF(Data!Q22<=45,"36-45","46+"))) -> 18-25 | AT22: =IF(AS22="18-25","Young",IF(AS22="26-35","Early Career",IF(AS22="36-45","Mid Career","Senior"))) -> Young | AU22: =IF(Table_1[[#This Row],[Percent Salary Hike]]<=12,"10-12%",IF(Table_1[[#This Row],[Percent Salary Hike]]<=15,"13-15%",IF(Table_1[[#This Row],[Percent Salary Hike]]<=18,"16-18%",IF(Table_1[[#This Row],[Percent Salary Hike]]<=21,"19-21%","22%+")))) -> 16-18% | AV22: =IF(Table_1[[#This Row],[Years At Company]]<=2,"0-2 Years",IF(Table_1[[#This Row],[Years At Company]]<=5,"3-5 Years",IF(Table_1[[#This Row],[Years At Company]]<=8,"6-8 Years",IF(Table_1[[#This Row],[Years At Company]]<=11,"9-11 Years","12+ Years")))) -> 3-5 Years
A23: Yes | B23: Travel_Rarely | C23: 35 - 44 | D23: Ex-Employees | E23: Sales | F23: Life Sciences | G23: STAFF-27 | H23: 27 | I23: Male | J23: Sales Representative | K23: Single | L23: No | M23: Y | N23: 4 | O23: -2 | P23: 0 | Q23: 36 | R23: 1 | S23: 1 | T23: 1 | U23: 0 | V23: 1218 | W23: 9 | X23: Master's Degree | Y23: 1 | Z23: 3 | AA23: 82 | AB23: 2 | AC23: 1 | AD23: 2 | AE23: 3407 | AF23: 6986 | AG23: 7 | AH23: 23 | AI23: 4 | AJ23: 2 | AK23: 80 | AL23: 0 | AM23: 10 | AN23: 3 | AO23: 5 | AP23: 3 | AQ23: 0 | AR23: 3 | AS23: =IF(Data!Q23<=25,"18-25",IF(Data!Q23<=35,"26-35",IF(Data!Q23<=45,"36-45","46+"))) -> 36-45 | AT23: =IF(AS23="18-25","Young",IF(AS23="26-35","Early Career",IF(AS23="36-45","Mid Career","Senior"))) -> Mid Career | AU23: =IF(Table_1[[#This Row],[Percent Salary Hike]]<=12,"10-12%",IF(Table_1[[#This Row],[Percent Salary Hike]]<=15,"13-15%",IF(Table_1[[#This Row],[Percent Salary Hike]]<=18,"16-18%",IF(Table_1[[#This Row],[Percent Salary Hike]]<=21,"19-21%","22%+")))) -> 22%+ | AV23: =IF(Table_1[[#This Row],[Years At Company]]<=2,"0-2 Years",IF(Table_1[[#This Row],[Years At Company]]<=5,"3-5 Years",IF(Table_1[[#This Row],[Years At Company]]<=8,"6-8 Years",IF(Table_1[[#This Row],[Years At Company]]<=11,"9-11 Years","12+ Years")))) -> 3-5 Years
A24: No | B24: Travel_Rarely | C24: 25 - 34 | D24: Current Employees | E24: R&D | F24: Life Sciences | G24: STAFF-28 | H24: 28 | I24: Female | J24: Research Director | K24: Single | L24: No | M24: Y | N24: 4 | O24: -2 | P24: 0 | Q24: 34 | R24: 0 | T24: 0 | U24: 1 | V24: 419 | W24: 7 | X24: Master's Degree | Y24: 1 | Z24: 1 | AA24: 53 | AB24: 3 | AC24: 3 | AD24: 2 | AE24: 11994 | AF24: 21293 | AG24: 0 | AH24: 11 | AI24: 3 | AJ24: 3 | AK24: 80 | AL24: 0 | AM24: 13 | AN24: 3 | AO24: 12 | AP24: 6 | AQ24: 2 | AR24: 11 | AS24: =IF(Data!Q24<=25,"18-25",IF(Data!Q24<=35,"26-35",IF(Data!Q24<=45,"36-45","46+"))) -> 26-35 | AT24: =IF(AS24="18-25","Young",IF(AS24="26-35","Early Career",IF(AS24="36-45","Mid Career","Senior"))) -> Early Career | AU24: =IF(Table_1[[#This Row],[Percent Salary Hike]]<=12,"10-12%",IF(Table_1[[#This Row],[Percent Salary Hike]]<=15,"13-15%",IF(Table_1[[#This Row],[Percent Salary Hike]]<=18,"16-18%",IF(Table_1[[#This Row],[Percent Salary Hike]]<=21,"19-21%","22%+")))) -> 10-12% | AV24: =IF(Table_1[[#This Row],[Years At Company]]<=2,"0-2 Years",IF(Table_1[[#This Row],[Years At Company]]<=5,"3-5 Years",IF(Table_1[[#This Row],[Years At Company]]<=8,"6-8 Years",IF(Table_1[[#This Row],[Years At Company]]<=11,"9-11 Years","12+ Years")))) -> 12+ Years
A25: No | B25: Travel_Rarely | C25: Under 25 | D25: Current Employees | E25: R&D | F25: Life Sciences | G25: STAFF-30 | H25: 30 | I25: Male | J25: Research Scientist | K25: Single | L25: No | M25: Y | N25: 6 | O25: -2 | P25: 0 | Q25: 21 | R25: 0 | T25: 0 | U25: 1 | V25: 391 | W25: 15 | X25: Associates Degree | Y25: 1 | Z25: 3 | AA25: 96 | AB25: 3 | AC25: 1 | AD25: 2 | AE25: 1232 | AF25: 19281 | AG25: 1 | AH25: 14 | AI25: 3 | AJ25: 4 | AK25: 80 | AL25: 0 | AM25: 0 | AN25: 3 | AO25: 0 | AP25: 0 | AQ25: 0 | AR25: 0 | AS25: =IF(Data!Q25<=25,"18-25",IF(Data!Q25<=35,"26-35",IF(Data!Q25<=45,"36-45","46+"))) -> 18-25 | AT25: =IF(AS25="18-25","Young",IF(AS25="26-35","Early Career",IF(AS25="36-45","Mid Career","Senior"))) -> Young | AU25: =IF(Table_1[[#This Row],[Percent Salary Hike]]<=12,"10-12%",IF(Table_1[[#This Row],[Percent Salary Hike]]<=15,"13-15%",IF(Table_1[[#This Row],[Percent Salary Hike]]<=18,"16-18%",IF(Table_1[[#This Row],[Percent Salary Hike]]<=21,"19-21%","22%+")))) -> 13-15% | AV25: =IF(Table_1[[#This Row],[Years At Company]]<=2,"0-2 Years",IF(Table_1[[#This Row],[Years At Company]]<=5,"3-5 Years",IF(Table_1[[#This Row],[Years At Company]]<=8,"6-8 Years",IF(Table_1[[#This Row],[Years At Company]]<=11,"9-11 Years","12+ Years")))) -> 0-2 Years
A26: Yes | B26: Travel_Rarely | C26: 25 - 34 | D26: Ex-Employees | E26: R&D | F26: Medical | G26: STAFF-31 | H26: 31 | I26: Male | J26: Research Scientist | K26: Single | L26: No | M26: Y | N26: 2 | O26: -2 | P26: 0 | Q26: 34 | R26: 1 | S26: 1 | T26: 1 | U26: 0 | V26: 699 | W26: 6 | X26: High School | Y26: 1 | Z26: 2 | AA26: 83 | AB26: 3 | AC26: 1 | AD26: 4 | AE26: 2960 | AF26: 17102 | AG26: 2 | AH26: 11 | AI26: 3 | AJ26: 3 | AK26: 80 | AL26: 0 | AM26: 8 | AN26: 3 | AO26: 4 | AP26: 2 | AQ26: 1 | AR26: 3 | AS26: =IF(Data!Q26<=25,"18-25",IF(Data!Q26<=35,"26-35",IF(Data!Q26<=45,"36-45","46+"))) -> 26-35 | AT26: =IF(AS26="18-25","Young",IF(AS26="26-35","Early Career",IF(AS26="36-45","Mid Career","Senior"))) -> Early Career | AU26: =IF(Table_1[[#This Row],[Percent Salary Hike]]<=12,"10-12%",IF(Table_1[[#This Row],[Percent Salary Hike]]<=15,"13-15%",IF(Table_1[[#This Row],[Percent Salary Hike]]<=18,"16-18%",IF(Table_1[[#This Row],[Percent Salary Hike]]<=21,"19-21%","22%+")))) -> 10-12% | AV26: =IF(Table_1[[#This Row],[Years At Company]]<=2,"0-2 Years",IF(Table_1[[#This Row],[Years At Company]]<=5,"3-5 Years",IF(Table_1[[#This Row],[Years At Company]]<=8,"6-8 Years",IF(Table_1[[#This Row],[Years At Company]]<=11,"9-11 Years","12+ Years")))) -> 3-5 Years
